<?xml version="1.0"?>
<robot xmlns:xacro="http://www.ros.org/wiki/xacro"  name="robot">

    <xacro:include filename="inertial_macros.xacro"/>

    <material name="white">
        <color rgba="1 1 1 1" />
    </material>

    <material name="orange">
        <color rgba="1 0.3 0.1 1"/>
    </material>

    <material name="blue">
        <color rgba="0.2 0.2 1 1"/>
    </material>

    <material name="black">
        <color rgba="0 0 0 1"/>
    </material>

    <!-- base link -->

    <link name="base_link">
        
    </link>

    <!-- base footprint -->

    <joint name="base_footprint_joint" type="fixed">
        <parent link="base_link"/>
        <child link="base_footprint"/>
        <origin xyz="0 0 0" rpy="0 0 0"/>
    </joint>

    <link name="base_footprint">
    </link>

    <!-- chassis -->

    <joint name="chassis_joint" type="fixed">
        <parent link="base_link"/>
        <child link="chassis"/>
        <origin xyz="0 0 0" rpy="0 0 0"/>
    </joint>

    <link name="chassis">
        <visual>
        <origin xyz="0 0 0.2475"/>
            <geometry>
                <box size="0.54 0.55 0.345"/>
            </geometry>
            <material name="white"/>
        </visual>
        <collision>
        <origin xyz="0.0 0.0 0.2475"/>
            <geometry>
                <box size="0.54 0.55 0.345"/>
            </geometry>
            <material name="white"/>
        </collision>
        <xacro:inertial_box mass="5.0" x="0.54" y="0.55" z="0.345">
            <origin xyz="0 0 0.05" rpy="0 0 0"/>
        </xacro:inertial_box>
    </link>

    <!-- left wheel -->

    <joint name="left_wheel_joint" type="continuous">
        <parent link="base_link"/>
        <child link="left_wheel"/>
        <origin xyz="0 0.1675 0.06" rpy="-${pi/2} 0 0"/>
        <axis xyz="0 0 1"/>
    </joint>

    <link name="left_wheel">
        <visual>
            <geometry>
                <cylinder radius="0.06" length="0.023"/>
            </geometry>
            <material name="black" />
        </visual>
        <collision>
            <geometry>
                <cylinder radius="0.06" length="0.023"/>
            </geometry>
            <material name="black" />
        </collision>
        <xacro:inertial_cylinder mass="0.2" length="0.023" radius="0.06">
            <origin xyz="0 0 0" rpy="0 0 0"/>
        </xacro:inertial_cylinder>
    </link>

    <!-- right wheel -->

    <joint name="right_wheel_joint" type="continuous">
        <parent link="base_link"/>
        <child link="right_wheel"/>
        <origin xyz="0 -0.1675 0.06" rpy="${pi/2} 0 0"/>
        <axis xyz="0 0 -1"/>
    </joint>

    <link name="right_wheel">
        <visual>
            <geometry>
                <cylinder radius="0.06" length="0.023"/>
            </geometry>
            <material name="black" />
        </visual>
        <collision>
            <geometry>
                <cylinder radius="0.06" length="0.023"/>
            </geometry>
            <material name="black" />
        </collision>
        <xacro:inertial_cylinder mass="0.2" length="0.023" radius="0.06">
            <origin xyz="0 0 0" rpy="0 0 0"/>
        </xacro:inertial_cylinder>
    </link>
    
    <!-- front caster wheel -->
    <joint name="front_caster_joint" type="fixed">
        <parent link="chassis"/>
        <child link="front_caster_wheel"/>
        <origin xyz="0.2325 0 0.0375"/>
    </joint>

    <link name="front_caster_wheel">
        <visual>
            <geometry>
                <sphere radius="0.0375"/>
            </geometry>
            <material name="black"/>
        </visual>
        <collision>
            <geometry>
                <sphere radius="0.0375"/>
            </geometry>
        </collision>
        <xacro:inertial_sphere mass="0.05" radius="0.0375">
            <origin xyz="0 0 0" rpy="0 0 0"/>
        </xacro:inertial_sphere>
    </link>

    <!-- rear caster wheel -->
    <joint name="rear_caster_joint" type="fixed">
        <parent link="chassis"/>
        <child link="rear_caster_wheel"/>
        <origin xyz="-0.2325 0 0.0375"/>
    </joint>

    <link name="rear_caster_wheel">
        <visual>
            <geometry>
                <sphere radius="0.0375"/>
            </geometry>
            <material name="black"/>
        </visual>
        <collision>
            <geometry>
                <sphere radius="0.0375"/>
            </geometry>
        </collision>
        <xacro:inertial_sphere mass="0.05" radius="0.0375">
            <origin xyz="0 0 0" rpy="0 0 0"/>
        </xacro:inertial_sphere>
    </link>

    <!-- Gazebo color ref -->
    <gazebo reference="base_link">
        <material>
            Gazebo/White
        </material>
    </gazebo>

    <gazebo reference="left_wheel">
        <material>
            Gazebo/Black
        </material>
    </gazebo>

    <gazebo reference="right_wheel">
        <material>
            Gazebo/Black
        </material>
    </gazebo>

    <gazebo reference="front_caster_wheel">
        <material>
            Gazebo/Black
        </material>
        <mu1 value="0.001"/>
        <mu2 value="0.001"/>
    </gazebo>

    <gazebo reference="rear_caster_wheel">
        <material>
            Gazebo/Black
        </material>
        <mu1 value="0.001"/>
        <mu2 value="0.001"/>
    </gazebo>

</robot>